<mujoco model="robotis_op">
    <compiler angle="degree" inertiafromgeom="true" meshdir="robotis_op_meshes/"/>
    <size nconmax="100" njmax="500" nstack="-1"/>    
    <default>
    	<joint armature="1" stiffness="0" damping="0.01" limited="true" axis="0 0 1" pos="0 0 0"/>
    	<!--<joint limited='true' frictional="true" frictionloss="0.2" damping="1.06" armature="0.011" axis="0 0 1" pos="0 0 0"/>-->
        <geom conaffinity="1" condim="1" contype="1" margin="0.001" material="geom"/>
        <motor ctrllimited="true" ctrlrange="-.4 .4"/>
    </default>
    <option integrator="RK4" iterations="50" solver="PGS" timestep="0.003">
        <!-- <flags solverstat="enable" energy="enable"/>-->
    </option>
    <size nkey="5" nuser_geom="1"/>
    <visual>
        <map fogend="5" fogstart="3"/>
    </visual>
    <asset>
    	<mesh file="body_coll.stl"/>
		<mesh file="neck_coll.stl"/>
		<mesh file="head_coll.stl"/>
		<mesh file="l_shoulder_coll.stl"/>
		<mesh file="l_arm_high_coll.stl"/>
		<mesh file="l_arm_low_coll.stl" scale="0.001 0.001 0.001"/>
		<mesh file="r_shoulder_coll.stl"/>
		<mesh file="r_arm_high_coll.stl"/>
		<mesh file="r_arm_low_coll.stl" scale="0.001 0.001 0.001"/>		
		<mesh file="l_pelvis_coll.stl"/>
		<mesh file="l_thigh1_coll.stl"/>
		<mesh file="l_thigh2_coll.stl"/>
		<mesh file="l_tibia_coll.stl"/>
		<mesh file="l_ankle1_coll.stl"/>
		<mesh file="l_ankle2_coll.stl"/>
		<mesh file="r_pelvis_coll.stl"/>
		<mesh file="r_thigh1_coll.stl"/>
		<mesh file="r_thigh2_coll.stl"/>
		<mesh file="r_tibia_coll.stl"/>
		<mesh file="r_ankle1_coll.stl"/>
		<mesh file="r_ankle2_coll.stl"/>
		
        <material name="MatPlastic" specular=".8" shininess=".6" reflectance="0.5" rgba=".4 .41 .4 1"/>
		<material name="MatFrame" specular="1.2" shininess=".1" reflectance="0.5" rgba=".21 .2 .2 1"/>
			
        <texture builtin="gradient" height="100" rgb1=".4 .5 .6" rgb2="0 0 0" type="skybox" width="100"/>
        <!-- <texture builtin="gradient" height="100" rgb1="1 1 1" rgb2="0 0 0" type="skybox" width="100"/>-->
        <texture builtin="flat" height="1278" mark="cross" markrgb="1 1 1" name="texgeom" random="0.01" rgb1="0.8 0.6 0.4" rgb2="0.8 0.6 0.4" type="cube" width="127"/>
        <texture builtin="checker" height="100" name="texplane" rgb1="0 0 0" rgb2="0.8 0.8 0.8" type="2d" width="100"/>
        <material name="MatPlane" reflectance="0.5" shininess="1" specular="1" texrepeat="60 60" texture="texplane"/>
        <material name="geom" texture="texgeom" texuniform="true"/>       	        
    </asset>

    <contact>       
        <exclude body1="head" body2="torso"/>
		<exclude body1="l_foot" body2="l_tibia"/>
        <exclude body1="r_foot" body2="r_tibia"/>
    </contact>	
    
    <worldbody>
        <light cutoff="100" diffuse="1 1 1" dir="-0 0 -1.3" directional="true" exponent="1" pos="0.5 0.1 0.8" specular=".1 .1 .1"/>
        <geom condim="3" friction="1 .1 .1" material="MatPlane" name="floor" pos="0 0 0" rgba="0.8 0.9 0.8 1" size="20 20 0.125" type="plane"/>
        <!-- <geom condim="3" material="MatPlane" name="floor" pos="0 0 0" size="10 10 0.125" type="plane"/>-->
        <body name="torso" pos="0 0 0.4">
            <joint armature="0" damping="0" limited="false" name="root" pos="0 0 0" stiffness="0" type="free"/>
            <geom mesh="body_coll" type="mesh" material="MatPlastic"/>
	        <body name="neck" pos="0 0 0.0235" quat="0.707107 0 0 0.707107">
	        	<inertial diaginertia="0.00482356 0.00482356 0.00482356" mass="0.0243577" pos="0.001424 -0.016567 -0.007128" quat="0.640564 0.00150549 0.00338323 0.767896"/>
            	<joint armature="0.01" name="head_yaw" range="-180.0 180.0" stiffness="10" damping="5" type="hinge"/>
            	<geom mesh="neck_coll" type="mesh" contype="0" conaffinity="0" material="MatFrame"/>
            	<body name="head" pos="0 0 0.02715" quat="0.5 -0.5 -0.5 0.5">
            		<inertial diaginertia="0.158397 0.123969 0.1178" mass="0.158042" pos="6.4e-005 -0.018565 -0.007667" quat="0.504401 0.495706 -0.489128 0.510499"/>
               		<joint armature="0.01" name="head_pitch" range="-25.0 55.0" stiffness="10" damping="5" type="hinge"/>
               		<geom mesh="head_coll" type="mesh" material="MatPlastic"/>
            	</body>
         	</body>
           	<body name="l_pelvis" pos="-0.005 0.037 -0.09355" quat="0 0.707107 0.707107 0">
           		<inertial diaginertia="0.122641 0.11137 0.0411301" mass="0.027069" pos="0 0.00048 0.018437" quat="0.998273 -0.0514899 -0.00396715 0.0279885"/>
            	<joint armature="0.01" name="l_hip_yaw" range="-53.0 123.0" stiffness="2.5" damping="1.0" type="hinge"/>
            	<geom mesh="l_pelvis_coll" type="mesh" contype="0" conaffinity="0" material="MatFrame"/>
            	<body name="l_thigh1" pos="0 0 0.028652" quat="0.707107 0.707107 0 0">
            		<inertial diaginertia="0.114985 0.0979692 0.0327798" mass="0.167107" pos="7.9e-005 0.018242 0.013873" quat="0.485806 0.506867 -0.504884 0.502165"/>
               		<joint armature="0.01" name="l_hip_roll" range="-59.0 45.0" stiffness="1" damping="0.5" type="hinge"/>
               		<geom mesh="l_thigh1_coll" type="mesh" material="MatFrame"/>
               		<body name="1_thigh2" pos="0 0 0" quat="0.5 0.5 -0.5 -0.5">
               			<inertial diaginertia="0.114985 0.0979692 0.0327798" mass="0.119043" pos="-0.062965 -0.000323 0.000692" quat="0.485806 0.506867 -0.504884 0.502165"/>
                  		<joint armature="0.01" name="l_hip_pitch" range="-29.0 110.0" type="hinge"/>
                  		<geom mesh="l_thigh2_coll" type="mesh" material="MatPlastic"/>
                  		<body name="l_tibia" pos="-0.093 0 0">
                  			<inertial diaginertia="0.115891 0.0933882 0.043901" mass="0.0703098" pos="-0.053955 0.006548 -0.000592" quat="0.456916 0.538297 -0.548699 0.447654"/>
                     		<joint armature="1" name="l_knee" range="-130.0 6.0" type="hinge"/>
                     		<geom mesh="l_tibia_coll" type="mesh" material="MatPlastic"/>
                     		<body name="l_ankle1" pos="-0.093 0 0" quat="0 1 0 0">
                     			<inertial diaginertia="0.120855 0.109532 0.0411304" mass="0.167108" pos="-0.000214 -0.018536 0.013873" quat="0.997965 0.0519065 0.00385358 -0.0368208"/>
                        		<joint armature="0.01" name="l_ankle_pitch" range="-80.0 72.0" stiffness="1" damping="0.5" type="hinge"/>
                        		<geom mesh="l_ankle1_coll" type="mesh" material="MatFrame"/>
		                        <body name="l_foot" pos="0 0 0" quat="0.707107 -0.707107 0 0">
		                        	<inertial diaginertia="0.120855 0.109532 0.0411304" mass="0.0794462" pos="-0.025995 -0.009506 -0.000503" quat="0.997965 0.0519065 0.00385358 -0.0368208"/>
                           			<joint armature="0.01" name="l_ankle_roll" range="-63.0 44.0" stiffness="1" damping="0.5" type="hinge"/>
                           			<geom mesh="l_ankle2_coll" type="mesh" material="MatPlastic" contype="0" conaffinity="0"/>
						   			<geom type="box" pos="-.027 -.01 0" size=".007 .032 .052" material="MatPlastic"/>
                        		</body>
                     		</body>
                  		</body>
               		</body>
            	</body>
         	</body>
         	<body name="r_pelvis" pos="-0.005 -0.037 -0.09355" quat="0 -0.707107 0.707107 0">
         		<inertial diaginertia="0.122641 0.11137 0.0411301" mass="0.027069" pos="0 0.00048 0.018437" quat="0.998273 -0.0514899 -0.00396715 0.0279885"/>
            	<joint armature="0.01" name="r_hip_yaw" range="-123.0 53.0" stiffness="2.5" damping="1.0" type="hinge"/>
            	<geom mesh="r_pelvis_coll" type="mesh" contype="0" conaffinity="0" material="MatFrame"/>
		        <body name="r_thigh1" pos="0 0 0.028652" quat="0.707107 -0.707107 0 0">
		        	<inertial diaginertia="0.114985 0.0979692 0.0327798" mass="0.167107" pos="7.9e-005 -0.018242 0.0138735" quat="0.485806 0.506867 -0.504884 0.502165"/>
               		<joint armature="0.01" name="r_hip_roll" range="-45.0 59.0" stiffness="1" damping="0.5" type="hinge"/>
               		<geom mesh="r_thigh1_coll" type="mesh" material="MatFrame"/>
                    <body name="r_thigh2" pos="0 0 0" quat="0.5 0.5 -0.5 -0.5">
                       	<inertial diaginertia="0.114985 0.0979692 0.0327798" mass="0.119043" pos="0.062965 -0.000323 0.000692" quat="0.485806 0.506867 -0.504884 0.502165"/>
                 		<joint armature="0.01" name="r_hip_pitch" range="-110.0 29.0" type="hinge"/>
                  		<geom mesh="r_thigh2_coll" type="mesh" material="MatPlastic"/>
                  		<body name="r_tibia" pos="0.093 0 0">
                  			<inertial diaginertia="0.115891 0.0933882 0.043901" mass="0.0703098" pos="0.053955 0.006548 -0.000592" quat="0.456916 0.538297 -0.548699 0.447654"/>
                    		<joint armature="1" name="r_knee" range="-6.0 130.0" type="hinge"/>
                    		<geom mesh="r_tibia_coll" type="mesh" material="MatPlastic"/>
                    		<body name="ankle1_r" pos="0.093 0 0" quat="0 1 0 0">
                    			<inertial diaginertia="0.120855 0.109532 0.0411304" mass="0.167108" pos="-0.000214 -0.018536 -0.013873" quat="0.997965 0.0519065 0.00385358 -0.0368208"/>
                       			<joint armature="0.01" name="r_ankle_pitch" range="-72.0 80.0" stiffness="1" damping="0.5" type="hinge"/>
                       			<geom mesh="r_ankle1_coll" type="mesh" material="MatFrame"/>
                                   <body name="r_foot" pos="0 0 0" quat="0.707107 -0.707107 0 0">
                                   	<inertial diaginertia="0.120855 0.109532 0.0411304" mass="0.0794462" pos="0.025995 -0.009506 -0.000503" quat="0.997965 0.0519065 0.00385358 -0.0368208"/>
                       				<joint armature="0.01" name="r_ankle_roll" range="-44.0 63.0" stiffness="1" damping="0.5" type="hinge"/>
                       				<geom mesh="r_ankle2_coll" type="mesh" material="MatPlastic" contype="0" conaffinity="0" />
					   				<geom type="box" pos=".027 -.01 0" size=".007 .032 .052" material="MatPlastic"/>
                        		</body>
                     		</body>
                  		</body>
               		</body>
            	</body>
         	</body>
         	<body name="l_shoulder" pos="0 0.06035 0" quat="0.5 -0.5 -0.5 -0.5">
         		<inertial diaginertia="0.0118742 0.00851644 0.00537304" mass="0.013" pos="-0.0135226 0.0102641 0.00139357" quat="0.89853 0.0814684 0.0409894 0.429332"/>
                <joint armature="0.005" name="l_shoulder_pitch" range="-150.0 150.0" stiffness="1" type="hinge"/>
                <geom mesh="l_shoulder_coll" type="mesh" contype="0" conaffinity="0" material="MatFrame"/>
                <body name="l_arm_high" pos="-0.016 0 0.025" quat="0.5 0.5 0.5 -0.5">
                	<inertial diaginertia="0.122178 0.113353 0.0379938" mass="0.17837715" pos="-0.036239 0.000734 0.00066" quat="0.713991 0.698029 0.0283632 -0.0465622"/>
                	<!--<joint armature="0.01" name="l_shoulder_roll" range="80.0 90.0" stiffness="1.0" type="hinge"/>-->
                  	<joint armature="0.005" name="l_shoulder_roll" range="-90.0 90.0" stiffness="1" type="hinge"/>
                  	<geom mesh="l_arm_high_coll" type="mesh" material="MatPlastic"/>
                  	<body name="l_arm_low" pos="-0.06 0 -0.016" quat="0 0 0.707107 0.707107">
                  		<inertial diaginertia="0.0875091 0.0872503 0.0201335" mass="0.037" pos=".013 -.015 0" quat=".707107 0 0 .315"/>
                  		<joint armature="0.005" name="l_elbow" range="55.0 75.0" stiffness="0" type="hinge"/>
                     	<!--<joint armature="0.01" name="l_elbow" range="-75.0 90.0" stiffness="1.0" type="hinge"/>-->
						<geom mesh="l_arm_low_coll" type="mesh" pos="0.022 -0.046 -0.0825" quat="0.5 -0.5 0.5 0.5" material="MatPlastic"/>                     	
                  	</body>
               	</body>
            </body>
            <body name="r_shoulder" pos="0 -0.06035 0" quat="-0.5 -0.5 0.5 -0.5">
            	<inertial diaginertia="0.0118742 0.00851644 0.00537304" mass="0.013" pos="-0.013523 0.010264 0.001394" quat="0.89853 0.0814684 0.0409894 0.429332"/>
                <joint armature="0.005" name="r_shoulder_pitch" range="-150.0 150.0" stiffness="1" type="hinge"/>
                <geom mesh="r_shoulder_coll" type="mesh" contype="0" conaffinity="0" material="MatFrame"/>
               	<body name="r_arm_high" pos="-0.016 0 0.025" quat="0.5 -0.5 0.5 0.5" >
               		<inertial diaginertia="0.122178 0.113353 0.0379938" mass="0.168377" pos="-0.036239 0.000734 -0.00066" quat="0.713991 0.698029 0.0283632 -0.0465622"/>
               		<!--<joint armature="0.01" name="r_shoulder_roll" range="-90.0 -80.0" stiffness="1.0" type="hinge"/>-->
                  	<joint armature="0.005" name="r_shoulder_roll" range="-90.0 90.0" stiffness="1" type="hinge"/>
                  	<geom mesh="r_arm_high_coll" type="mesh" material="MatPlastic"/>
                  	<body name="r_arm_low" pos="-0.06 0 -0.016" quat="0 0 0.707107 0.707107">
                  		<inertial diaginertia="0.0875091 0.0872503 0.0201335" mass="0.0592885" pos="0 0 0" quat="0.362962 0.448533 -0.589325 0.565485"/>
                  		<joint armature="0.005" name="r_elbow" range="55.0 75.0" stiffness="0" type="hinge"/>
                     	<!--<joint armature="0.01" name="r_elbow" range="-90.0 75.0" stiffness="1.0" type="hinge"/>-->
						<geom mesh="r_arm_low_coll" type="mesh" pos="0.022 -0.046 0.0825" quat="0.5 -0.5 0.5 0.5" material="MatPlastic"/>
                  	</body>
               	</body>
            </body>
        </body>
    </worldbody>
    
    <actuator>
    	<motor gear="30"	joint="l_hip_yaw"    		name="l_hip_yaw"/>
		<motor gear="10"	joint="l_hip_roll"   		name="l_hip_roll"/>
		<motor gear="5"	joint="l_hip_pitch"  		name="l_hip_pitch"/>
		<motor gear="5"		joint="l_knee"       		name="l_knee"/>
		<motor gear="10"	joint="l_ankle_pitch"		name="l_ankle_pitch"/>
		<motor gear="10"	joint="l_ankle_roll" 		name="l_ankle_roll"/>
		
		<motor gear="30"	joint="r_hip_yaw"    		name="r_hip_yaw"/>
		<motor gear="10"	joint="r_hip_roll"   		name="r_hip_roll"/>
		<motor gear="5"	joint="r_hip_pitch"  		name="r_hip_pitch"/>
		<motor gear="5"		joint="r_knee"       		name="r_knee"/>
		<motor gear="10"	joint="r_ankle_pitch"		name="r_ankle_pitch"/>
		<motor gear="10"	joint="r_ankle_roll" 		name="r_ankle_roll"/>
		<!--
		<motor gear="10"	joint="l_shoulder_pitch"	name="l_shoulder_pitch"/>
		<motor gear="10"	joint="l_shoulder_roll"		name="l_shoulder_roll"/>
 		<motor gear="10"	joint="l_elbow"				name="l_elbow"/>
		<motor gear="10"	joint="r_shoulder_pitch"	name="r_shoulder_pitch"/>
		<motor gear="10"	joint="r_shoulder_roll"		name="r_shoulder_roll"/>
 		<motor gear="10"	joint="r_elbow"				name="r_elbow"/>
		-->
    </actuator>
</mujoco>